<?xml version="1.0" ?>
<!-- =================================================================================== -->
<!-- |    This document was autogenerated by xacro from allegro_hand_description_right.xacro | -->
<!-- |    EDITING THIS FILE BY HAND IS NOT RECOMMENDED                                 | -->
<!-- =================================================================================== -->
<robot name="allegro_hand_left" xmlns:xacro="http://www.ros.org/wiki/xacro">
  <!-- ======================== BASE PARAMS ========================= -->
  <!-- ======================== FINGER PARAMS ======================== -->
  <!-- full height from joint to tip. when used,
    the radius of the finger tip sphere will be subtracted
    and one fixed link will be added for the tip. -->
  <!-- ========================= THUMB PARAMS ========================= -->
  <!-- ========================= LIMITS ========================= -->
  <!-- ============================================================================= -->
  <!-- PALM -->
 <link name="world"/>
  <joint name="global" type="fixed">
        <parent link="world"/>
        <child link="palm_link"/>
        <origin xyz="0 0 0.0" rpy="0 0 0"/>
  </joint>
  <link name="palm_link">
    <visual>
      <geometry>
        <mesh filename="package://allegro_hand_controllers/meshes/left_hand_G.stl" scale="0.001 0.001 0.001"/>
      </geometry>
      <origin rpy="0 0 1.57" xyz="0.02 0.0 -0.1"/>
      <material name="black">
        <color rgba="0.2 0.2 0.2 1"/>
      </material>
    </visual>
    <collision>
      <geometry>
        <mesh filename="package://allegro_hand_controllers/meshes/left_hand_G.stl" scale="0.001 0.001 0.001"/>
      </geometry>
 <origin rpy="0 0 1.57" xyz="0.02 0.0 -0.1"/>
    </collision>
    <inertial>
      <origin rpy="0 0 0" xyz="0 0 0.0475"/>
      <mass value="0.4154"/>
      <inertia ixx="1e-4" ixy="0.0" ixz="0.0" iyy="1e-4" iyz="0.0" izz="1e-4"/>
    </inertial>
  </link>
  <!-- ============================================================================= -->
  <!-- FINGERS -->
  <!-- RIGHT HAND due to which finger is number 0 -->
  <!-- for LEFT HAND switch the sign of the **offset_origin_y** and **finger_angle_r** parameters-->
  <!-- [LINK 0, 4, 8] -->
  <link name="link_0_0">
        <visual>
      <geometry>
        <mesh filename="package://allegro_hand_controllers/meshes/new_l1.stl" scale="0.001 0.001 0.001"/>
      </geometry>
      <origin rpy="0 0 -1.57" xyz="-0.0625 -0.022 0.168"/>
      <material name="black">
        <color rgba="0.2 0.2 0.2 1"/>
      </material>
    </visual>
    <collision>
      <geometry>
        <mesh filename="package://allegro_hand_controllers/meshes/new_l1.stl" scale="0.001 0.001 0.001"/>
      </geometry>
      <origin rpy="0 0 -1.57" xyz="-0.0625 -0.022 0.168"/>
    </collision>
    <inertial>
      <mass value="0.0176"/>
      <origin rpy="0 0 0" xyz="0 0 0"/>
      <inertia ixx="1.2854008e-05" ixy="2.04e-08" ixz="1.89e-06" iyy="1.225e-05" iyz="1.51e-07" izz="2.999e-06"/>
    </inertial>
  </link>
  <joint name="joint_0_0" type="revolute">
    <axis xyz="0 0 1"/>
    <limit effort="15" lower="-0.26" upper="0.29" velocity="7"/>
    <parent link="palm_link"/>
    <child link="link_0_0"/>
    <origin rpy="0.08726646255 0 0" xyz="0.0005 -0.0425 -0.005"/>
    <dynamics damping="3" friction="10"/>
  </joint>
  <!-- [LINK 1, 5, 9] -->
  <link name="link_1_0">
    <visual>
      <geometry>
        <mesh filename="package://allegro_hand_controllers/meshes/new_l2.stl" scale="0.001 0.001 0.001"/>
      </geometry>
      <origin rpy="0 0 -1.57" xyz="-0.0625 -0.022 0.1495"/>
      <material name="black"/>
    </visual>
    <collision>
      <geometry>
        <mesh filename="package://allegro_hand_controllers/meshes/new_l2.stl" scale="0.001 0.001 0.001"/>
      </geometry>
      <origin rpy="0 0 -1.57" xyz="-0.0625 -0.022 0.1495"/>
    </collision>
    <inertial>
      <mass value="0.086"/>
      <origin rpy="0 0 0" xyz="0 0 0"/>
      <inertia ixx="1.86e-05" ixy="1.68e-06" ixz="-6.16e-06" iyy="4.87e-05" iyz="3.51e-07" izz="5.57e-05"/>
    </inertial>
  </link>
  <joint name="joint_1_0" type="revolute">
    <limit effort="15" lower="-0.21" upper="1.79" velocity="7"/>
    <axis xyz="0 1 0"/>
    <parent link="link_0_0"/>
    <child link="link_1_0"/>
    <origin xyz="0 0 0.017"/>
    <dynamics damping="3" friction="5"/>
  </joint>
  <!-- [LINK 2, 6, 10]-->
  <link name="link_2_0">
    <visual>
      <geometry>
        <mesh filename="package://allegro_hand_controllers/meshes/new_l3.stl" scale="0.001 0.001 0.001"/>
      </geometry>
      <origin rpy="0 0 -1.57" xyz="-0.0625 -0.022 0.1065"/>
      <material name="black"/>
    </visual>
    <collision>
      <geometry>
        <mesh filename="package://allegro_hand_controllers/meshes/new_l3.stl" scale="0.001 0.001 0.001"/>
      </geometry>
      <origin rpy="0 0 -1.57" xyz="-0.0625 -0.022 0.1065"/>
    </collision>
    <inertial>
      <mass value="0.0367"/>
      <origin rpy="0 0 0" xyz="0 0 0"/>
      <inertia ixx="3.81e-06" ixy="5.72e-09" ixz="-9.97e-07" iyy="1.455e-05" iyz="2.63e-08" izz="1.29e-05"/>
    </inertial>
  </link>
  <joint name="joint_2_0" type="revolute">
    <axis xyz="0 1 0"/>
    <limit effort="15" lower="-0.12" upper="1.86" velocity="7"/>
    <parent link="link_1_0"/>
    <child link="link_2_0"/>
    <origin xyz="0 0 0.0431"/>
    <dynamics damping="8" friction="10"/>
  </joint>
  <!-- [LINK 3, 7, 11] -->
  <link name="link_3_0">
    <visual>
      <geometry>
        <mesh filename="package://allegro_hand_controllers/meshes/new_l4.stl" scale="0.001 0.001 0.001"/>
      </geometry>
      <origin rpy="0 0 -1.57" xyz="-0.0625 -0.022 0.0685"/>
      <material name="black"/>
    </visual>
    <collision>
      <geometry>
        <mesh filename="package://allegro_hand_controllers/meshes/new_l4.stl" scale="0.001 0.001 0.001"/>
      </geometry>
      <origin rpy="0 0 -1.57" xyz="-0.0625 -0.022 0.0685"/>
    </collision>
    <inertial>
      <mass value="0.004"/>
      <origin rpy="0 0 0" xyz="0 0 0"/>
      <inertia ixx="1.17e-06" ixy="5.09e-09" ixz="0.0" iyy="2.4e-06" iyz="0.0" izz="1.67e-06"/>
    </inertial>
  </link>
  <joint name="joint_3_0" type="revolute">
    <axis xyz="0 1 0"/>
    <limit effort="15" lower="-0.21" upper="1.85" velocity="7"/>
    <parent link="link_2_0"/>
    <child link="link_3_0"/>
    <origin xyz="0 0 0.038"/>
    <dynamics damping="10" friction="12"/>
  </joint>
  <!-- [FINGER TIP] -->
  <link name="link_3_0_tip">
    <visual>
      <geometry>
        <mesh filename="package://allegro_hand_controllers/meshes/finger_tip.stl" scale="0.001 0.001 0.001"/>
      </geometry>
       <origin rpy="0 0 -1.57" xyz="-0.05482 -0.01493 -0.01795"/>
      <material name="white">
        <color rgba=".9 .9 .9 1"/>
      </material>
    </visual>
    <collision>
      <geometry>
        <mesh filename="package://allegro_hand_controllers/meshes/finger_tip.stl" scale="0.001 0.001 0.001"/>
      </geometry>
       <origin rpy="0 0 -1.57" xyz="-0.05482 -0.01493 -0.01795"/>
    </collision>
    <inertial>
      <mass value="0.0017"/>
      <origin rpy="0 0 0" xyz="0 0 0"/>
      <inertia ixx="9.68e-07" ixy="0" ixz="0" iyy="9.68e-07" iyz="0" izz="9.68e-07"/>
    </inertial>
  </link>
  <joint name="joint_3_0_tip" type="fixed">
    <parent link="link_3_0"/>
    <child link="link_3_0_tip"/>
    <origin rpy="0 0 0" xyz="0 0 0.04"/>
  </joint>
  <!-- [LINK 0, 4, 8] -->
  <link name="link_4_0">
     <visual>
      <geometry>
        <mesh filename="package://allegro_hand_controllers/meshes/new_l1.stl" scale="0.001 0.001 0.001"/>
      </geometry>
      <origin rpy="0 0 -1.57" xyz="-0.0625 -0.022 0.167"/>
      <material name="black">
        <color rgba="0.2 0.2 0.2 1"/>
      </material>
    </visual>
    <collision>
      <geometry>
        <mesh filename="package://allegro_hand_controllers/meshes/new_l1.stl" scale="0.001 0.001 0.001"/>
      </geometry>
      <origin rpy="0 0 -1.57" xyz="-0.0625 -0.022 0.167"/>
    </collision>
    <inertial>
      <mass value="0.0176"/>
      <origin rpy="0 0 0" xyz="0 0 0"/>
      <inertia ixx="1.2854008e-05" ixy="2.04e-08" ixz="1.89e-06" iyy="1.225e-05" iyz="1.51e-07" izz="2.999e-06"/>
    </inertial>
  </link>
  <joint name="joint_4_0" type="revolute">
    <axis xyz="0 0 1"/>
    <limit effort="15" lower="-0.26" upper="0.26" velocity="7"/>
    <parent link="palm_link"/>
    <child link="link_4_0"/>
    <origin rpy="0.0 0 0" xyz="0 0 -0.002"/>
    <dynamics damping="3" friction="10"/>
  </joint>
  <!-- [LINK 1, 5, 9] -->
  <link name="link_5_0">
    <visual>
      <geometry>
        <mesh filename="package://allegro_hand_controllers/meshes/new_l2.stl" scale="0.001 0.001 0.001"/>
      </geometry>
      <origin rpy="0 0 -1.57" xyz="-0.0625 -0.022 0.1495"/>
      <material name="black"/>
    </visual>
    <collision>
      <geometry>
        <mesh filename="package://allegro_hand_controllers/meshes/new_l2.stl" scale="0.001 0.001 0.001"/>
      </geometry>
      <origin rpy="0 0 -1.57" xyz="-0.0625 -0.022 0.1495"/>
    </collision>
    <inertial>
      <mass value="0.086"/>
      <origin rpy="0 0 0" xyz="0 0 0"/>
      <inertia ixx="1.86e-05" ixy="1.68e-06" ixz="-6.16e-06" iyy="4.87e-05" iyz="3.51e-07" izz="5.57e-05"/>
    </inertial>
  </link>
  <joint name="joint_5_0" type="revolute">
    <limit effort="15" lower="-0.21" upper="1.79" velocity="7"/>
    <axis xyz="0 1 0"/>
    <parent link="link_4_0"/>
    <child link="link_5_0"/>
    <origin xyz="0 0 0.017"/>
    <dynamics damping="3" friction="5"/>
  </joint>
  <!-- [LINK 2, 6, 10]-->
  <link name="link_6_0">
   <visual>
      <geometry>
        <mesh filename="package://allegro_hand_controllers/meshes/new_l3.stl" scale="0.001 0.001 0.001"/>
      </geometry>
      <origin rpy="0 0 -1.57" xyz="-0.0625 -0.022 0.1065"/>
      <material name="black"/>
    </visual>
    <collision>
      <geometry>
        <mesh filename="package://allegro_hand_controllers/meshes/new_l3.stl" scale="0.001 0.001 0.001"/>
      </geometry>
      <origin rpy="0 0 -1.57" xyz="-0.0625 -0.022 0.1065"/>
    </collision>
    <inertial>
      <mass value="0.0367"/>
      <origin rpy="0 0 0" xyz="0 0 0"/>
      <inertia ixx="3.81e-06" ixy="5.72e-09" ixz="-9.97e-07" iyy="1.455e-05" iyz="2.63e-08" izz="1.29e-05"/>
    </inertial>
  </link>
  <joint name="joint_6_0" type="revolute">
    <axis xyz="0 1 0"/>
    <limit effort="15" lower="-0.12" upper="1.86" velocity="7"/>
    <parent link="link_5_0"/>
    <child link="link_6_0"/>
    <origin xyz="0 0 0.0431"/>
    <dynamics damping="8" friction="10"/>
  </joint>
  <!-- [LINK 3, 7, 11] -->
  <link name="link_7_0">
    <visual>
      <geometry>
        <mesh filename="package://allegro_hand_controllers/meshes/new_l4.stl" scale="0.001 0.001 0.001"/>
      </geometry>
      <origin rpy="0 0 -1.57" xyz="-0.0625 -0.022 0.0685"/>
      <material name="black"/>
    </visual>
    <collision>
      <geometry>
        <mesh filename="package://allegro_hand_controllers/meshes/new_l4.stl" scale="0.001 0.001 0.001"/>
      </geometry>
      <origin rpy="0 0 -1.57" xyz="-0.0625 -0.022 0.0685"/>
    </collision>
    <inertial>
      <mass value="0.004"/>
      <origin rpy="0 0 0" xyz="0 0 0"/>
      <inertia ixx="1.17e-06" ixy="5.09e-09" ixz="0.0" iyy="2.4e-06" iyz="0.0" izz="1.67e-06"/>
    </inertial>
  </link>
  <joint name="joint_7_0" type="revolute">
    <axis xyz="0 1 0"/>
    <limit effort="15" lower="-0.21" upper="1.85" velocity="7"/>
    <parent link="link_6_0"/>
    <child link="link_7_0"/>
    <origin xyz="0 0 0.038"/>
    <dynamics damping="10" friction="12"/>
  </joint>
  <!-- [FINGER TIP] -->
  <link name="link_7_0_tip">
    <visual>
      <geometry>
        <mesh filename="package://allegro_hand_controllers/meshes/finger_tip.stl" scale="0.001 0.001 0.001"/>
      </geometry>
       <origin rpy="0 0 -1.57" xyz="-0.05482 -0.01493 -0.01795"/>
      <material name="white">
        <color rgba=".9 .9 .9 1"/>
      </material>
    </visual>
    <collision>
      <geometry>
        <mesh filename="package://allegro_hand_controllers/meshes/finger_tip.stl" scale="0.001 0.001 0.001"/>
      </geometry>
        <origin rpy="0 0 -1.57" xyz="-0.05482 -0.01493 -0.01795"/>
    </collision>
    <inertial>
      <mass value="0.0017"/>
      <origin rpy="0 0 0" xyz="0 0 0"/>
      <inertia ixx="9.68e-07" ixy="0" ixz="0" iyy="9.68e-07" iyz="0" izz="9.68e-07"/>
    </inertial>
  </link>
  <joint name="joint_7_0_tip" type="fixed">
    <parent link="link_7_0"/>
    <child link="link_7_0_tip"/>
    <origin rpy="0 0 0" xyz="0 0 0.04"/>
  </joint>
  <!-- [LINK 0, 4, 8] -->
  <link name="link_8_0">
    <visual>
      <geometry>
        <mesh filename="package://allegro_hand_controllers/meshes/new_l1.stl" scale="0.001 0.001 0.001"/>
      </geometry>
      <origin rpy="0 0 -1.57" xyz="-0.0625 -0.022 0.168"/>
      <material name="black">
        <color rgba="0.2 0.2 0.2 1"/>
      </material>
    </visual>
    <collision>
      <geometry>
        <mesh filename="package://allegro_hand_controllers/meshes/new_l1.stl" scale="0.001 0.001 0.001"/>
      </geometry>
      <origin rpy="0 0 -1.57" xyz="-0.0625 -0.022 0.168"/>
    </collision>
    <inertial>
      <mass value="0.0176"/>
      <origin rpy="0 0 0" xyz="0 0 0"/>
      <inertia ixx="1.2854008e-05" ixy="2.04e-08" ixz="1.89e-06" iyy="1.225e-05" iyz="1.51e-07" izz="2.999e-06"/>
    </inertial>
  </link>
  <joint name="joint_8_0" type="revolute">
    <axis xyz="0 0 1"/>
    <limit effort="15" lower="-0.3" upper="0.3" velocity="7"/>
    <parent link="palm_link"/>
    <child link="link_8_0"/>
    <origin rpy="-0.08726646255 0 0" xyz="0.0005 0.0425 -0.005"/>
    <dynamics damping="3" friction="10"/>
  </joint>
  <!-- [LINK 1, 5, 9] -->
  <link name="link_9_0">
    <visual>
      <geometry>
        <mesh filename="package://allegro_hand_controllers/meshes/new_l2.stl" scale="0.001 0.001 0.001"/>
      </geometry>
      <origin rpy="0 0 -1.57" xyz="-0.0625 -0.022 0.1495"/>
      <material name="black"/>
    </visual>
    <collision>
      <geometry>
        <mesh filename="package://allegro_hand_controllers/meshes/new_l2.stl" scale="0.001 0.001 0.001"/>
      </geometry>
      <origin rpy="0 0 -1.57" xyz="-0.0625 -0.022 0.1495"/>
    </collision>
    <inertial>
      <mass value="0.086"/>
      <origin rpy="0 0 0" xyz="0 0 0"/>
      <inertia ixx="1.86e-05" ixy="1.68e-06" ixz="-6.16e-06" iyy="4.87e-05" iyz="3.51e-07" izz="5.57e-05"/>
    </inertial>
  </link>
  <joint name="joint_9_0" type="revolute">
    <limit effort="15" lower="-0.01" upper="1.6" velocity="7"/>
    <axis xyz="0 1 0"/>
    <parent link="link_8_0"/>
    <child link="link_9_0"/>
    <origin xyz="0 -0.000 0.017"/>
    <dynamics damping="3" friction="5"/>
  </joint>
  <!-- [LINK 2, 6, 10]-->
  <link name="link_10_0">
    <visual>
      <geometry>
        <mesh filename="package://allegro_hand_controllers/meshes/new_l3.stl" scale="0.001 0.001 0.001"/>
      </geometry>
      <origin rpy="0 0 -1.57" xyz="-0.0625 -0.022 0.1065"/>
      <material name="black"/>
    </visual>
    <collision>
      <geometry>
        <mesh filename="package://allegro_hand_controllers/meshes/new_l3.stl" scale="0.001 0.001 0.001"/>
      </geometry>
      <origin rpy="0 0 -1.57" xyz="-0.0625 -0.022 0.1065"/>
    </collision>
    <inertial>
      <mass value="0.0367"/>
      <origin rpy="0 0 0" xyz="0 0 0"/>
      <inertia ixx="3.81e-06" ixy="5.72e-09" ixz="-9.97e-07" iyy="1.455e-05" iyz="2.63e-08" izz="1.29e-05"/>
    </inertial>
  </link>
  <joint name="joint_10_0" type="revolute">
    <axis xyz="0 1 0"/>
    <limit effort="15" lower="-0.07" upper="1.86" velocity="7"/>
    <parent link="link_9_0"/>
    <child link="link_10_0"/>
    <origin xyz="0 -0.000 0.0431"/>
    <dynamics damping="8" friction="10"/>
  </joint>
  <!-- [LINK 3, 7, 11] -->
  <link name="link_11_0">
    <visual>
      <geometry>
        <mesh filename="package://allegro_hand_controllers/meshes/new_l4.stl" scale="0.001 0.001 0.001"/>
      </geometry>
      <origin rpy="0 0 -1.57" xyz="-0.0625 -0.022 0.0685"/>
      <material name="black"/>
    </visual>
    <collision>
      <geometry>
        <mesh filename="package://allegro_hand_controllers/meshes/new_l4.stl" scale="0.001 0.001 0.001"/>
      </geometry>
      <origin rpy="0 0 -1.57" xyz="-0.0625 -0.022 0.0685"/>
    </collision>
    <inertial>
      <mass value="0.004"/>
      <origin rpy="0 0 0" xyz="0 0 0"/>
      <inertia ixx="1.17e-06" ixy="5.09e-09" ixz="0.0" iyy="2.4e-06" iyz="0.0" izz="1.67e-06"/>
    </inertial>
  </link>
  <joint name="joint_11_0" type="revolute">
    <axis xyz="0 1 0"/>
    <limit effort="15" lower="-0.02" upper="2.01" velocity="7"/>
    <parent link="link_10_0"/>
    <child link="link_11_0"/>
    <origin xyz="0 0 0.038"/>
    <dynamics damping="10" friction="12"/>
  </joint>
  <!-- [FINGER TIP] -->
  <link name="link_11_0_tip">
    <visual>
      <geometry>
        <mesh filename="package://allegro_hand_controllers/meshes/finger_tip.stl" scale="0.001 0.001 0.001"/>
      </geometry>
       <origin rpy="0 0 -1.57" xyz="-0.05482 -0.01493 -0.01795"/>
      <material name="white">
        <color rgba=".9 .9 .9 1"/>
      </material>
    </visual>
    <collision>
      <geometry>
        <mesh filename="package://allegro_hand_controllers/meshes/finger_tip.stl" scale="0.001 0.001 0.001"/>
      </geometry>
       <origin rpy="0 0 -1.57" xyz="-0.05482 -0.01493 -0.01795"/>
    </collision>
    <inertial>
      <mass value="0.0017"/>
      <origin rpy="0 0 0" xyz="0 0 0"/>
      <inertia ixx="9.68e-07" ixy="0" ixz="0" iyy="9.68e-07" iyz="0" izz="9.68e-07"/>
    </inertial>
  </link>
  <joint name="joint_11_0_tip" type="fixed">
    <parent link="link_11_0"/>
    <child link="link_11_0_tip"/>
    <origin rpy="0 0 0" xyz="0 0 0.04"/>
  </joint>
  <!-- THUMB -->
  <!-- [LINK 12] -->
  <link name="link_12_0">
    <visual>
      <geometry>
        <mesh filename="package://allegro_hand_controllers/meshes/t1_set.stl" scale="0.001 0.001 0.001"/>
      </geometry>
      <origin rpy="3.926991 3.14 3.14" xyz="0.021 -0.1145 0.0725"/>
      <material name="black">
        <color rgba=".2 .2 .2 1"/>
      </material>
    </visual>
    <collision>
      <geometry>
        <mesh filename="package://allegro_hand_controllers/meshes/t1_set.stl" scale="0.001 0.001 0.001"/>
      </geometry>
      <origin rpy="3.926991 3.14 3.14" xyz="0.021 -0.1145 0.0725"/>
    </collision>
    <inertial>
      <mass value="0.0446"/>
      <origin rpy="0 0 0" xyz="0 0 0"/>
      <inertia ixx="5.44e-5" ixy="4.0e-07" ixz="-1.12e-07" iyy="9.19e-06" iyz="1.07e-05" izz="4.8e-05"/>
    </inertial>
  </link>
  <joint name="joint_12_0" type="revolute">
    <axis xyz="-1 0 0"/>
    <limit effort="15" lower="-1.78" upper="0.00" velocity="7"/>
    <parent link="palm_link"/>
    <child link="link_12_0"/>
    <origin rpy="3.14 -1.483529863 -1.5707963259" xyz="0.002 -0.027 -0.06342"/>
    <dynamics damping="3" friction="10"/>
  </joint>
  <!-- [LINK 13] -->
  <link name="link_13_0">
    <visual>
      <geometry>
        <mesh filename="package://allegro_hand_controllers/meshes/t2_set.stl" scale="0.001 0.001 0.001"/>
      </geometry>
      <origin rpy="3.14 3.14 1.57" xyz="-0.138 -0.0605 0.2143"/>
      <material name="black">
        <color rgba=".2 .2 .2 1"/>
      </material>
    </visual>
    <collision>
      <geometry>
        <mesh filename="package://allegro_hand_controllers/meshes/t2_set.stl" scale="0.001 0.001 0.001"/>
      </geometry>
      <origin rpy="3.14 3.14 1.57" xyz="-0.138 -0.0605 0.2143"/>
    </collision>
    <inertial>
      <mass value="0.0173"/>
      <origin rpy="0 0 0" xyz="0 0 0"/>
      <inertia ixx="1.52e-05" ixy="-2.09e-08" ixz="-9.8e-09" iyy="1.3323e-05" iyz="-2.04e-06" izz="2.85e-06"/>
    </inertial>
  </link>
  <joint name="joint_13_0" type="revolute">
    <axis xyz="0 0 1"/>
       <limit effort="15" lower="1.57" upper="3.22" velocity="7"/>
    <parent link="link_12_0"/>
    <child link="link_13_0"/>
    <origin xyz="-0.001 0.00 0.06874"/>
    <dynamics damping="3" friction="5"/>
  </joint>
  <!-- [LINK 14] -->
  <link name="link_14_0">
    <visual>
      <geometry>
        <mesh filename="package://allegro_hand_controllers/meshes/t3_set.stl" scale="0.001 0.001 0.001"/>
      </geometry>
      <origin rpy="3.14 3.14 1.57" xyz="-0.1265 -0.061 0.166"/>
      <material name="black">
      </material>
    </visual>
    <collision>
      <geometry>
        <mesh filename="package://allegro_hand_controllers/meshes/t3_set.stl" scale="0.001 0.001 0.001"/>
      </geometry>
      <origin rpy="3.14 3.14 1.57" xyz="-0.1265 -0.061 0.166"/>
    </collision>
    <inertial>
      <mass value="0.03607"/>
      <origin rpy="0 0 0" xyz="0 0 0"/>
      <inertia ixx="3.7e-06" ixy="2.43e-07" ixz="6.48e-07" iyy="1.54e-05" iyz="-3.11e-08" izz="1.388e-05"/>
    </inertial>
  </link>
  <joint name="joint_14_0" type="revolute">
    <axis xyz="0 1 0"/>
    <!--<limit effort="15" lower="-0.54" upper="1.53" velocity="7"/>-->
           <limit effort="15" lower="-1.85" upper="0.05" velocity="7"/>
    <parent link="link_13_0"/>
    <child link="link_14_0"/>
    <origin xyz="0 0 0.00"/>
    <dynamics damping="3" friction="10"/>
  </joint>
  <!-- [LINK 15] -->
  <link name="link_15_0">
    <visual>
      <geometry>
         <mesh filename="package://allegro_hand_controllers/meshes/t4_set.stl" scale="0.001 0.001 0.001"/>
      </geometry>
      <origin rpy="3.14 3.14 1.57" xyz="-0.149 -0.061 0.096"/>
      <material name="black">
      </material>
    </visual>
    <collision>
      <geometry>
         <mesh filename="package://allegro_hand_controllers/meshes/t4_set.stl" scale="0.001 0.001 0.001"/>
      </geometry>
      <origin rpy="3.14 3.14 1.57" xyz="-0.149 -0.061 0.096"/>
    </collision>
    <inertial>
      <mass value="0.0334"/>
      <origin rpy="0 0 0" xyz="0 0 0"/>
      <inertia ixx="2.94e-06" ixy="1.244e-07" ixz="3.52e-07" iyy="1.13e-05" iyz="-3.11e-08" izz="1.06e-05"/>
    </inertial>
  </link>
  <joint name="joint_15_0" type="revolute">
    <axis xyz="0 1 0"/>
    <limit effort="15" lower="-1.80" upper="0.09" velocity="7"/>
    <parent link="link_14_0"/>
    <child link="link_15_0"/>
    <origin xyz="0 0 0.038"/>
    <dynamics damping="3" friction="12"/>
  </joint>
  <!-- [FINGER TIP] -->
  <link name="link_15_0_tip">
    <visual>
      <geometry>
        <mesh filename="package://allegro_hand_controllers/meshes/finger_tip_silicon.stl" scale="0.001 0.001 0.001"/>
      </geometry>
      <origin rpy="0 0 3.14" xyz="-0.014 0.0545 -0.0172"/>
      <material name="white">
        <color rgba=".9 .9 .9 1"/>
      </material>
    </visual>
    <collision>
      <geometry>
        <mesh filename="package://allegro_hand_controllers/meshes/finger_tip_silicon.stl" scale="0.001 0.001 0.001"/>
      </geometry>
      <origin rpy="0 0 3.14" xyz="-0.014 0.0545 -0.0172"/>
    </collision>
    <inertial>
      <mass value="0.0014"/>
      <origin rpy="0 0 0" xyz="0 0 0"/>
      <inertia ixx="9.68e-07" ixy="0" ixz="0" iyy="9.68e-07" iyz="0" izz="9.68e-07"/>
    </inertial>
  </link>
  <joint name="joint_15_0_tip" type="fixed">
    <parent link="link_15_0"/>
    <child link="link_15_0_tip"/>
    <origin rpy="0 0 0" xyz="0 0 0.05"/>
  </joint>
  <!-- ============================================================================= -->
  <!-- THUMB MACRO -->
  <!-- END THUMB MACRO -->
  <!-- THREE FINGER MACRO -->
  <!-- [[END]] THREE FINGER MACRO -->
</robot>
